Workbook

Sheet parte 1
B2: Inversion Incial (Año 0)
B3: Rubro | C3: Monto
B4: Adquisición De Terreno Para Planta (1.5 Has) | C4: 35000 | F4: Capacidad de producion mensual | I4: 23000
B5: Contrucción De La Planta De Procesamiento | C5: 180000
B6: Adquisión E Instalación De Maquinarias Y Equipos | C6: 90000
B7: Equipo De Oficina Y Comunicación | C7: 7000
B8: Camioneta De Reparto ( 3tn) | C8: 150000
B9: Certificacion De Licencias | C9: 12000
B10: Desarrollo De Proveedores Y Cadema De Frío | C10: 45000
B11: Total Inversión Fija | C11: =SUM(C4:C10) -> 519000
B12: Capital De Trabajo | C12: =C170 -> 468186.67
B13: Total De Capital De Trabajo | C13: =-C12 -> -468186.67
B14: Total De Inversión | C14: =C11+C13 -> 50813.333
B17: Costo variable Unitarios por kilogramos de pulpa procesada
B19: Rubro | C19: Unidad De Medida | D19: Valor Unitario | E19: Unidades utilizadas | F19: Costo Fijo | G19: Costo Variable | H19: Costo Total
B21: Fruta fresca (mango/maracuyá) | C21: Kg | D21: 5.5 | E21: 20 | G21: =D21*E21 -> 110 | H21: =F21+G21 -> 110
B22: Lavado y selección | C22: Kg | D22: 0.35 | E22: 1 | G22: =D22*E22 -> 0.35 | H22: =F22+G22 -> 0.35
B23: Despulpado | C23: Kg | D23: 0.55 | E23: 1 | G23: =D23*E23 -> 0.55 | H23: =F23+G23 -> 0.55
B24: Pasteurización | C24: Kg | D24: 0.45 | E24: 1 | G24: =D24*E24 -> 0.45 | H24: =F24+G24 -> 0.45
B25: Empaquetado y sellado | C25: Kg | D25: 0.35 | E25: 1 | G25: =D25*E25 -> 0.35 | H25: =F25+G25 -> 0.35
B26: Costos De Producción Mes 1 | F26: =SUM(F21:F25) -> 0 | G26: =SUM(G21:G25) -> 111.7 | H26: =SUM(H21:H25) -> 111.7
B30: Costos Operativos Primer Mes En Nuevos Soles
B32: Rubro | F32: Monto Mensual
B33: Gastos De Administración
B34: Servicios Publicos (Agua, Luz, Desague, Internet) | F34: 1200
B35: Mantenimiento De Instlaciones Y Equipos | F35: 700
B36: Personal Administrativo 2 Profesionales) | F36: 11000
B37: Personal De Producción (6 Operarios) | F37: 9000
B38: Marketin Y Publicidad Online | F38: 300
B39: Seguridad Y Vigilancia De Planta | F39: 600
B40: Gastos De Distribución De Flete Por Cliente | F40: =0.3*I4 -> 6900
B41: Total Costos Operativos | F41: =SUM(F34:F40) -> 29700
B46: Costo Unitario
B48: Precio de venta | C48: 32
B54: Rubro | C54: 0 | D54: 1 | E54: 2 | F54: 3 | G54: 4 | H54: 5 | I54: 6 | J54: 7 | K54: 8 | L54: 9 | M54: 10 | N54: 11 | O54: 12
B55: Ventas en kilogramos | D55: 1200 | E55: 1400 | F55: 1500 | G55: 17000 | H55: 1800 | I55: 1800 | J55: 1700 | K55: 1600 | L55: 1900 | M55: 2000 | N55: 2100 | O55: 2200
B56: Precio De Venta (Por Unidad) | D56: =C48 -> 32 | E56: =D56 -> 32 | F56: =E56 -> 32 | G56: =F56 -> 32 | H56: =G56 -> 32 | I56: =H56 -> 32 | J56: =I56 -> 32 | K56: =J56 -> 32 | L56: =K56 -> 32 | ... O56: =N56 -> 32
B59: Tabla De Depreciaciones
B60: Activos | C60: Valor Compra | D60: Vida Util | E60: Dep Anual (1-6) | F60: Dep Anual (7-12) | G60: Dep Acumulada | H60: Valor De Recupero
B61: ='parte 1'!B5 -> Contrucción De La Planta De Procesamiento | C61: ='parte 1'!C5 -> 180000 | D61: 30 | E61: =C61*(1/D61) -> 6000 | F61: =E61 -> 6000 | G61: =E61*12 -> 72000 | H61: =C61-G61 -> 108000
...

Sheet parte 2
B2: Inversion Incial (Año 0)
B3: Rubro | C3: Monto
B4: Adquisición De Terreno Para Planta (1.5 Has) | C4: 35000 | F4: Capacidad de producion mensual | I4: 23000
B5: Contrucción De La Planta De Procesamiento | C5: 180000
B6: Adquisión E Instalación De Maquinarias Y Equipos | C6: 90000
B7: Equipo De Oficina Y Comunicación | C7: 7000
B8: Camioneta De Reparto ( 3tn) | C8: 150000
B9: Certificacion De Licencias | C9: 12000
B10: Desarrollo De Proveedores Y Cadema De Frío | C10: 45000
B11: Terreno | C11: 30000
B12: Almacen | C12: 80000
B13: Total Inversión Fija | C13: =SUM(C4:C10) -> 519000
B14: Capital De Trabajo | C14: ='parte 2'!C112 -> -28000
B15: Total De Capital De Trabajo | C15: =-C14 -> 28000
B16: Total De Inversión | C16: =C13+C15 -> 547000
B19: Costo variable Unitarios por kilogramos de pulpa procesada
B21: Rubro | C21: Unidad De Medida | D21: Valor Unitario | E21: Unidades utilizadas | F21: Costo Fijo | G21: Costo Variable | H21: Costo Total
B23: Fruta fresca (mango/maracuyá) | C23: Kg | D23: 5.5 | E23: 20 | G23: =D23*E23 -> 110 | H23: =F23+G23 -> 110
B24: Lavado y selección | C24: Kg | D24: 0.35 | E24: 1 | G24: =D24*E24 -> 0.35 | H24: =F24+G24 -> 0.35
B25: Despulpado | C25: Kg | D25: 0.55 | E25: 1 | G25: =D25*E25 -> 0.55 | H25: =F25+G25 -> 0.55
B26: Pasteurización | C26: Kg | D26: 0.45 | E26: 1 | G26: =D26*E26 -> 0.45 | H26: =F26+G26 -> 0.45
B27: Empaquetado y sellado | C27: Kg | D27: 0.35 | E27: 1 | G27: =D27*E27 -> 0.35 | H27: =F27+G27 -> 0.35
B28: Costos De Producción Mes 1 | F28: =SUM(F23:F27) -> 0 | G28: =SUM(G23:G27) -> 111.7 | H28: =SUM(H23:H27) -> 111.7
B32: Costos Operativos Primer Mes En Nuevos Soles
B34: Rubro | F34: Monto Mensual
B35: Gastos De Administración
B36: Servicios Publicos (Agua, Luz, Desague, Internet) | F36: 1200
B37: Mantenimiento De Instlaciones Y Equipos | F37: 700
B38: Personal Administrativo 2 Profesionales) | F38: 11000
B39: Personal De Producción (6 Operarios) | F39: 9000
B40: Marketin Y Publicidad Online | F40: 300
B41: Seguridad Y Vigilancia De Planta | F41: 600
B42: Gastos De Distribución De Flete Por Cliente | F42: =0.3*I4 -> 6900
B43: Total Costos Operativos | F43: =SUM(F36:F42) -> 29700
B48: Costo Unitario
B50: Precio de venta | C50: 32
B56: Rubro | C56: 0 | D56: 1 | E56: 2 | F56: 3 | G56: 4 | H56: 5 | I56: 6 | J56: 7 | K56: 8 | L56: 9 | M56: 10 | N56: 11 | O56: 12
B57: Ventas en kilogramos | D57: 1200 | E57: 1400 | F57: 1500 | G57: 17000 | H57: 1800 | I57: 1800 | J57: 1700 | K57: 1600 | L57: 1900 | M57: 2000 | N57: 2100 | O57: 2200
B58: Precio De Venta (Por Unidad) | D58: =C50 -> 32 | E58: =D58 -> 32 | F58: =E58 -> 32 | G58: =F58 -> 32 | H58: =G58 -> 32 | I58: =H58 -> 32 | J58: =I58 -> 32 | K58: =J58 -> 32 | L58: =K58 -> 32 | ... O58: =N58 -> 32
B61: Tabla De Depreciaciones
...

Sheet preguntas
